12-12-2024,16:57:38 - ERROR - Error occurred: 1064 (42000): You have an error in your SQL syntax; check the manual that corresponds to your MySQL server version for the right syntax to use near '%s' at line 1 - [userController > userController.py > getUserByName]
12-12-2024,16:57:48 - ERROR - Error occurred: 1064 (42000): You have an error in your SQL syntax; check the manual that corresponds to your MySQL server version for the right syntax to use near '%s' at line 1 - [userController > userController.py > getUserByName]
12-12-2024,16:57:49 - ERROR - Error occurred: 1064 (42000): You have an error in your SQL syntax; check the manual that corresponds to your MySQL server version for the right syntax to use near '%s' at line 1 - [userController > userController.py > getUserByName]
12-12-2024,16:57:51 - ERROR - Error occurred: 1064 (42000): You have an error in your SQL syntax; check the manual that corresponds to your MySQL server version for the right syntax to use near '%s' at line 1 - [userController > userController.py > getUserByName]
12-12-2024,16:57:52 - ERROR - Error occurred: 1064 (42000): You have an error in your SQL syntax; check the manual that corresponds to your MySQL server version for the right syntax to use near '%s' at line 1 - [userController > userController.py > getUserByName]
12-12-2024,16:57:52 - ERROR - Error occurred: 1064 (42000): You have an error in your SQL syntax; check the manual that corresponds to your MySQL server version for the right syntax to use near '%s' at line 1 - [userController > userController.py > getUserByName]
12-12-2024,16:58:00 - ERROR - Error occurred: 1064 (42000): You have an error in your SQL syntax; check the manual that corresponds to your MySQL server version for the right syntax to use near '%s' at line 1 - [userController > userController.py > getUserByName]
12-12-2024,17:00:03 - ERROR - Error occurred: 'str' object is not callable - [userController > userController.py > getUserByName]
12-12-2024,17:00:05 - ERROR - Error occurred: 'str' object is not callable - [userController > userController.py > getUserByName]
12-12-2024,17:01:39 - ERROR - Error occurred: Unread result found - [userController > userController.py > getUserByName]
12-12-2024,17:01:40 - ERROR - Error occurred: Unread result found - [userController > userController.py > getUserByName]
12-12-2024,17:01:40 - ERROR - Error occurred: Unread result found - [userController > userController.py > getUserByName]
12-12-2024,17:01:41 - ERROR - Error occurred: Unread result found - [userController > userController.py > getUserByName]
12-12-2024,17:01:41 - ERROR - Error occurred: Unread result found - [userController > userController.py > getUserByName]
12-12-2024,17:01:44 - ERROR - Error occurred: Unread result found - [userController > userController.py > getUserByName]
12-12-2024,17:01:48 - ERROR - Error occurred: Unread result found - [userController > userController.py > getUserByName]
12-12-2024,17:01:50 - ERROR - Error occurred: Unread result found - [userController > userController.py > getUsers]
12-12-2024,17:01:53 - ERROR - Error occurred: Unread result found - [userController > userController.py > getUsers]
12-12-2024,17:01:54 - ERROR - Error occurred: Unread result found - [userController > userController.py > getUsers]
12-12-2024,17:01:54 - ERROR - Error occurred: Unread result found - [userController > userController.py > getUsers]
12-12-2024,17:01:54 - ERROR - Error occurred: Unread result found - [userController > userController.py > getUsers]
12-12-2024,17:01:55 - ERROR - Error occurred: Unread result found - [userController > userController.py > getUsers]
12-12-2024,17:01:55 - ERROR - Error occurred: Unread result found - [userController > userController.py > getUsers]
12-12-2024,17:01:55 - ERROR - Error occurred: Unread result found - [userController > userController.py > getUsers]
12-12-2024,17:01:55 - ERROR - Error occurred: Unread result found - [userController > userController.py > getUsers]
12-12-2024,17:01:55 - ERROR - Error occurred: Unread result found - [userController > userController.py > getUsers]
12-12-2024,17:01:55 - ERROR - Error occurred: Unread result found - [userController > userController.py > getUsers]
12-12-2024,17:01:56 - ERROR - Error occurred: Unread result found - [userController > userController.py > getUsers]
12-12-2024,17:01:56 - ERROR - Error occurred: Unread result found - [userController > userController.py > getUsers]
12-12-2024,17:01:57 - ERROR - Error occurred: Unread result found - [userController > userController.py > getUsers]
12-12-2024,17:04:50 - ERROR - Error on request:
Traceback (most recent call last):
  File "/usr/local/lib/python3.13/site-packages/werkzeug/serving.py", line 370, in run_wsgi
    execute(self.server.app)
    ~~~~~~~^^^^^^^^^^^^^^^^^
  File "/usr/local/lib/python3.13/site-packages/werkzeug/serving.py", line 331, in execute
    application_iter = app(environ, start_response)
  File "/usr/local/lib/python3.13/site-packages/flask/app.py", line 1536, in __call__
    return self.wsgi_app(environ, start_response)
           ~~~~~~~~~~~~~^^^^^^^^^^^^^^^^^^^^^^^^^
  File "/usr/local/lib/python3.13/site-packages/flask/app.py", line 1514, in wsgi_app
    response = self.handle_exception(e)
  File "/usr/local/lib/python3.13/site-packages/flask/app.py", line 1511, in wsgi_app
    response = self.full_dispatch_request()
  File "/usr/local/lib/python3.13/site-packages/flask/app.py", line 919, in full_dispatch_request
    rv = self.handle_user_exception(e)
  File "/usr/local/lib/python3.13/site-packages/flask/app.py", line 917, in full_dispatch_request
    rv = self.dispatch_request()
  File "/usr/local/lib/python3.13/site-packages/flask/app.py", line 902, in dispatch_request
    return self.ensure_sync(self.view_functions[rule.endpoint])(**view_args)  # type: ignore[no-any-return]
           ~~~~~~~~~~~~~~~~~~~~~~~~~~~~~~~~~~~~~~~~~~~~~~~~~~~~^^^^^^^^^^^^^
  File "/app/controller/userController.py", line 41, in createUser
    if self.userMysqlRepository.createUser()[0].startswith(200):
       ^^^^^^^^^^^^^^^^^^^^^^^^^^^^^^^^^^^^^^^^^^^^^^^^^^^
AttributeError: 'int' object has no attribute 'startswith' - [_internal > _internal.py > _log]
12-12-2024,17:09:29 - ERROR - Error on request:
Traceback (most recent call last):
  File "/usr/local/lib/python3.13/site-packages/werkzeug/serving.py", line 370, in run_wsgi
    execute(self.server.app)
    ~~~~~~~^^^^^^^^^^^^^^^^^
  File "/usr/local/lib/python3.13/site-packages/werkzeug/serving.py", line 331, in execute
    application_iter = app(environ, start_response)
  File "/usr/local/lib/python3.13/site-packages/flask/app.py", line 1536, in __call__
    return self.wsgi_app(environ, start_response)
           ~~~~~~~~~~~~~^^^^^^^^^^^^^^^^^^^^^^^^^
  File "/usr/local/lib/python3.13/site-packages/flask/app.py", line 1514, in wsgi_app
    response = self.handle_exception(e)
  File "/usr/local/lib/python3.13/site-packages/flask/app.py", line 1511, in wsgi_app
    response = self.full_dispatch_request()
  File "/usr/local/lib/python3.13/site-packages/flask/app.py", line 919, in full_dispatch_request
    rv = self.handle_user_exception(e)
  File "/usr/local/lib/python3.13/site-packages/flask/app.py", line 917, in full_dispatch_request
    rv = self.dispatch_request()
  File "/usr/local/lib/python3.13/site-packages/flask/app.py", line 902, in dispatch_request
    return self.ensure_sync(self.view_functions[rule.endpoint])(**view_args)  # type: ignore[no-any-return]
           ~~~~~~~~~~~~~~~~~~~~~~~~~~~~~~~~~~~~~~~~~~~~~~~~~~~~^^^^^^^^^^^^^
  File "/app/controller/userController.py", line 41, in createUser
    if str(self.userMysqlRepository.createUser()[0]).startswith(200):
       ~~~~~~~~~~~~~~~~~~~~~~~~~~~~~~~~~~~~~~~~~~~~~~~~~~~~~~~~^^^^^
TypeError: startswith first arg must be str or a tuple of str, not int - [_internal > _internal.py > _log]
12-12-2024,17:14:51 - ERROR - Error on request:
Traceback (most recent call last):
  File "/usr/local/lib/python3.13/site-packages/werkzeug/serving.py", line 370, in run_wsgi
    execute(self.server.app)
    ~~~~~~~^^^^^^^^^^^^^^^^^
  File "/usr/local/lib/python3.13/site-packages/werkzeug/serving.py", line 331, in execute
    application_iter = app(environ, start_response)
  File "/usr/local/lib/python3.13/site-packages/flask/app.py", line 1536, in __call__
    return self.wsgi_app(environ, start_response)
           ~~~~~~~~~~~~~^^^^^^^^^^^^^^^^^^^^^^^^^
  File "/usr/local/lib/python3.13/site-packages/flask/app.py", line 1514, in wsgi_app
    response = self.handle_exception(e)
  File "/usr/local/lib/python3.13/site-packages/flask/app.py", line 1511, in wsgi_app
    response = self.full_dispatch_request()
  File "/usr/local/lib/python3.13/site-packages/flask/app.py", line 919, in full_dispatch_request
    rv = self.handle_user_exception(e)
  File "/usr/local/lib/python3.13/site-packages/flask/app.py", line 917, in full_dispatch_request
    rv = self.dispatch_request()
  File "/usr/local/lib/python3.13/site-packages/flask/app.py", line 902, in dispatch_request
    return self.ensure_sync(self.view_functions[rule.endpoint])(**view_args)  # type: ignore[no-any-return]
           ~~~~~~~~~~~~~~~~~~~~~~~~~~~~~~~~~~~~~~~~~~~~~~~~~~~~^^^^^^^^^^^^^
  File "/app/controller/userController.py", line 55, in delUser
    res = self.userMysqlRepository.delUser()
TypeError: UserMysqlRepository.delUser() missing 1 required positional argument: 'name' - [_internal > _internal.py > _log]
12-12-2024,17:15:20 - ERROR - Error on request:
Traceback (most recent call last):
  File "/usr/local/lib/python3.13/site-packages/werkzeug/serving.py", line 370, in run_wsgi
    execute(self.server.app)
    ~~~~~~~^^^^^^^^^^^^^^^^^
  File "/usr/local/lib/python3.13/site-packages/werkzeug/serving.py", line 331, in execute
    application_iter = app(environ, start_response)
  File "/usr/local/lib/python3.13/site-packages/flask/app.py", line 1536, in __call__
    return self.wsgi_app(environ, start_response)
           ~~~~~~~~~~~~~^^^^^^^^^^^^^^^^^^^^^^^^^
  File "/usr/local/lib/python3.13/site-packages/flask/app.py", line 1514, in wsgi_app
    response = self.handle_exception(e)
  File "/usr/local/lib/python3.13/site-packages/flask/app.py", line 1511, in wsgi_app
    response = self.full_dispatch_request()
  File "/usr/local/lib/python3.13/site-packages/flask/app.py", line 919, in full_dispatch_request
    rv = self.handle_user_exception(e)
  File "/usr/local/lib/python3.13/site-packages/flask/app.py", line 917, in full_dispatch_request
    rv = self.dispatch_request()
  File "/usr/local/lib/python3.13/site-packages/flask/app.py", line 902, in dispatch_request
    return self.ensure_sync(self.view_functions[rule.endpoint])(**view_args)  # type: ignore[no-any-return]
           ~~~~~~~~~~~~~~~~~~~~~~~~~~~~~~~~~~~~~~~~~~~~~~~~~~~~^^^^^^^^^^^^^
  File "/app/controller/userController.py", line 55, in delUser
    res = self.userMysqlRepository.delUser()
TypeError: UserMysqlRepository.delUser() missing 1 required positional argument: 'name' - [_internal > _internal.py > _log]
12-12-2024,17:15:27 - ERROR - Error on request:
Traceback (most recent call last):
  File "/usr/local/lib/python3.13/site-packages/werkzeug/serving.py", line 370, in run_wsgi
    execute(self.server.app)
    ~~~~~~~^^^^^^^^^^^^^^^^^
  File "/usr/local/lib/python3.13/site-packages/werkzeug/serving.py", line 331, in execute
    application_iter = app(environ, start_response)
  File "/usr/local/lib/python3.13/site-packages/flask/app.py", line 1536, in __call__
    return self.wsgi_app(environ, start_response)
           ~~~~~~~~~~~~~^^^^^^^^^^^^^^^^^^^^^^^^^
  File "/usr/local/lib/python3.13/site-packages/flask/app.py", line 1514, in wsgi_app
    response = self.handle_exception(e)
  File "/usr/local/lib/python3.13/site-packages/flask/app.py", line 1511, in wsgi_app
    response = self.full_dispatch_request()
  File "/usr/local/lib/python3.13/site-packages/flask/app.py", line 919, in full_dispatch_request
    rv = self.handle_user_exception(e)
  File "/usr/local/lib/python3.13/site-packages/flask/app.py", line 917, in full_dispatch_request
    rv = self.dispatch_request()
  File "/usr/local/lib/python3.13/site-packages/flask/app.py", line 902, in dispatch_request
    return self.ensure_sync(self.view_functions[rule.endpoint])(**view_args)  # type: ignore[no-any-return]
           ~~~~~~~~~~~~~~~~~~~~~~~~~~~~~~~~~~~~~~~~~~~~~~~~~~~~^^^^^^^^^^^^^
  File "/app/controller/userController.py", line 55, in delUser
    res = self.userMysqlRepository.delUser()
TypeError: UserMysqlRepository.delUser() missing 1 required positional argument: 'name' - [_internal > _internal.py > _log]
12-12-2024,17:33:52 - ERROR - inputs data are not valid - [userController > userController.py > operation1]
12-12-2024,17:36:00 - ERROR - <bound method UserMysqlRepository.getUsers of <repository.mysql.userMysqlRepository.UserMysqlRepository object at 0xffff0b322660>> - [userController > userController.py > operation1]
12-12-2024,17:37:00 - ERROR - Error on request:
Traceback (most recent call last):
  File "/usr/local/lib/python3.13/site-packages/werkzeug/serving.py", line 370, in run_wsgi
    execute(self.server.app)
    ~~~~~~~^^^^^^^^^^^^^^^^^
  File "/usr/local/lib/python3.13/site-packages/werkzeug/serving.py", line 331, in execute
    application_iter = app(environ, start_response)
  File "/usr/local/lib/python3.13/site-packages/flask/app.py", line 1536, in __call__
    return self.wsgi_app(environ, start_response)
           ~~~~~~~~~~~~~^^^^^^^^^^^^^^^^^^^^^^^^^
  File "/usr/local/lib/python3.13/site-packages/flask/app.py", line 1514, in wsgi_app
    response = self.handle_exception(e)
  File "/usr/local/lib/python3.13/site-packages/flask/app.py", line 1511, in wsgi_app
    response = self.full_dispatch_request()
  File "/usr/local/lib/python3.13/site-packages/flask/app.py", line 919, in full_dispatch_request
    rv = self.handle_user_exception(e)
  File "/usr/local/lib/python3.13/site-packages/flask/app.py", line 917, in full_dispatch_request
    rv = self.dispatch_request()
  File "/usr/local/lib/python3.13/site-packages/flask/app.py", line 902, in dispatch_request
    return self.ensure_sync(self.view_functions[rule.endpoint])(**view_args)  # type: ignore[no-any-return]
           ~~~~~~~~~~~~~~~~~~~~~~~~~~~~~~~~~~~~~~~~~~~~~~~~~~~~^^^^^^^^^^^^^
TypeError: UserController.delUser() got an unexpected keyword argument 'name' - [_internal > _internal.py > _log]
12-12-2024,17:37:05 - ERROR - Error on request:
Traceback (most recent call last):
  File "/usr/local/lib/python3.13/site-packages/werkzeug/serving.py", line 370, in run_wsgi
    execute(self.server.app)
    ~~~~~~~^^^^^^^^^^^^^^^^^
  File "/usr/local/lib/python3.13/site-packages/werkzeug/serving.py", line 331, in execute
    application_iter = app(environ, start_response)
  File "/usr/local/lib/python3.13/site-packages/flask/app.py", line 1536, in __call__
    return self.wsgi_app(environ, start_response)
           ~~~~~~~~~~~~~^^^^^^^^^^^^^^^^^^^^^^^^^
  File "/usr/local/lib/python3.13/site-packages/flask/app.py", line 1514, in wsgi_app
    response = self.handle_exception(e)
  File "/usr/local/lib/python3.13/site-packages/flask/app.py", line 1511, in wsgi_app
    response = self.full_dispatch_request()
  File "/usr/local/lib/python3.13/site-packages/flask/app.py", line 919, in full_dispatch_request
    rv = self.handle_user_exception(e)
  File "/usr/local/lib/python3.13/site-packages/flask/app.py", line 917, in full_dispatch_request
    rv = self.dispatch_request()
  File "/usr/local/lib/python3.13/site-packages/flask/app.py", line 902, in dispatch_request
    return self.ensure_sync(self.view_functions[rule.endpoint])(**view_args)  # type: ignore[no-any-return]
           ~~~~~~~~~~~~~~~~~~~~~~~~~~~~~~~~~~~~~~~~~~~~~~~~~~~~^^^^^^^^^^^^^
TypeError: UserController.delUser() got an unexpected keyword argument 'name' - [_internal > _internal.py > _log]
12-12-2024,17:40:57 - ERROR - Error on request:
Traceback (most recent call last):
  File "/usr/local/lib/python3.13/site-packages/werkzeug/serving.py", line 370, in run_wsgi
    execute(self.server.app)
    ~~~~~~~^^^^^^^^^^^^^^^^^
  File "/usr/local/lib/python3.13/site-packages/werkzeug/serving.py", line 331, in execute
    application_iter = app(environ, start_response)
  File "/usr/local/lib/python3.13/site-packages/flask/app.py", line 1536, in __call__
    return self.wsgi_app(environ, start_response)
           ~~~~~~~~~~~~~^^^^^^^^^^^^^^^^^^^^^^^^^
  File "/usr/local/lib/python3.13/site-packages/flask/app.py", line 1514, in wsgi_app
    response = self.handle_exception(e)
  File "/usr/local/lib/python3.13/site-packages/flask/app.py", line 1511, in wsgi_app
    response = self.full_dispatch_request()
  File "/usr/local/lib/python3.13/site-packages/flask/app.py", line 919, in full_dispatch_request
    rv = self.handle_user_exception(e)
  File "/usr/local/lib/python3.13/site-packages/flask/app.py", line 917, in full_dispatch_request
    rv = self.dispatch_request()
  File "/usr/local/lib/python3.13/site-packages/flask/app.py", line 902, in dispatch_request
    return self.ensure_sync(self.view_functions[rule.endpoint])(**view_args)  # type: ignore[no-any-return]
           ~~~~~~~~~~~~~~~~~~~~~~~~~~~~~~~~~~~~~~~~~~~~~~~~~~~~^^^^^^^^^^^^^
TypeError: UserController.getUserByName() got an unexpected keyword argument 'name' - [_internal > _internal.py > _log]
12-12-2024,17:41:02 - ERROR - Error on request:
Traceback (most recent call last):
  File "/usr/local/lib/python3.13/site-packages/werkzeug/serving.py", line 370, in run_wsgi
    execute(self.server.app)
    ~~~~~~~^^^^^^^^^^^^^^^^^
  File "/usr/local/lib/python3.13/site-packages/werkzeug/serving.py", line 331, in execute
    application_iter = app(environ, start_response)
  File "/usr/local/lib/python3.13/site-packages/flask/app.py", line 1536, in __call__
    return self.wsgi_app(environ, start_response)
           ~~~~~~~~~~~~~^^^^^^^^^^^^^^^^^^^^^^^^^
  File "/usr/local/lib/python3.13/site-packages/flask/app.py", line 1514, in wsgi_app
    response = self.handle_exception(e)
  File "/usr/local/lib/python3.13/site-packages/flask/app.py", line 1511, in wsgi_app
    response = self.full_dispatch_request()
  File "/usr/local/lib/python3.13/site-packages/flask/app.py", line 919, in full_dispatch_request
    rv = self.handle_user_exception(e)
  File "/usr/local/lib/python3.13/site-packages/flask/app.py", line 917, in full_dispatch_request
    rv = self.dispatch_request()
  File "/usr/local/lib/python3.13/site-packages/flask/app.py", line 902, in dispatch_request
    return self.ensure_sync(self.view_functions[rule.endpoint])(**view_args)  # type: ignore[no-any-return]
           ~~~~~~~~~~~~~~~~~~~~~~~~~~~~~~~~~~~~~~~~~~~~~~~~~~~~^^^^^^^^^^^^^
TypeError: UserController.getUserByName() got an unexpected keyword argument 'name' - [_internal > _internal.py > _log]
12-12-2024,17:42:03 - ERROR - Error on request:
Traceback (most recent call last):
  File "/usr/local/lib/python3.13/site-packages/werkzeug/serving.py", line 370, in run_wsgi
    execute(self.server.app)
    ~~~~~~~^^^^^^^^^^^^^^^^^
  File "/usr/local/lib/python3.13/site-packages/werkzeug/serving.py", line 331, in execute
    application_iter = app(environ, start_response)
  File "/usr/local/lib/python3.13/site-packages/flask/app.py", line 1536, in __call__
    return self.wsgi_app(environ, start_response)
           ~~~~~~~~~~~~~^^^^^^^^^^^^^^^^^^^^^^^^^
  File "/usr/local/lib/python3.13/site-packages/flask/app.py", line 1514, in wsgi_app
    response = self.handle_exception(e)
  File "/usr/local/lib/python3.13/site-packages/flask/app.py", line 1511, in wsgi_app
    response = self.full_dispatch_request()
  File "/usr/local/lib/python3.13/site-packages/flask/app.py", line 919, in full_dispatch_request
    rv = self.handle_user_exception(e)
  File "/usr/local/lib/python3.13/site-packages/flask/app.py", line 917, in full_dispatch_request
    rv = self.dispatch_request()
  File "/usr/local/lib/python3.13/site-packages/flask/app.py", line 902, in dispatch_request
    return self.ensure_sync(self.view_functions[rule.endpoint])(**view_args)  # type: ignore[no-any-return]
           ~~~~~~~~~~~~~~~~~~~~~~~~~~~~~~~~~~~~~~~~~~~~~~~~~~~~^^^^^^^^^^^^^
TypeError: UserController.getUserByName() got an unexpected keyword argument 'name' - [_internal > _internal.py > _log]
12-12-2024,17:42:05 - ERROR - Error on request:
Traceback (most recent call last):
  File "/usr/local/lib/python3.13/site-packages/werkzeug/serving.py", line 370, in run_wsgi
    execute(self.server.app)
    ~~~~~~~^^^^^^^^^^^^^^^^^
  File "/usr/local/lib/python3.13/site-packages/werkzeug/serving.py", line 331, in execute
    application_iter = app(environ, start_response)
  File "/usr/local/lib/python3.13/site-packages/flask/app.py", line 1536, in __call__
    return self.wsgi_app(environ, start_response)
           ~~~~~~~~~~~~~^^^^^^^^^^^^^^^^^^^^^^^^^
  File "/usr/local/lib/python3.13/site-packages/flask/app.py", line 1514, in wsgi_app
    response = self.handle_exception(e)
  File "/usr/local/lib/python3.13/site-packages/flask/app.py", line 1511, in wsgi_app
    response = self.full_dispatch_request()
  File "/usr/local/lib/python3.13/site-packages/flask/app.py", line 919, in full_dispatch_request
    rv = self.handle_user_exception(e)
  File "/usr/local/lib/python3.13/site-packages/flask/app.py", line 917, in full_dispatch_request
    rv = self.dispatch_request()
  File "/usr/local/lib/python3.13/site-packages/flask/app.py", line 902, in dispatch_request
    return self.ensure_sync(self.view_functions[rule.endpoint])(**view_args)  # type: ignore[no-any-return]
           ~~~~~~~~~~~~~~~~~~~~~~~~~~~~~~~~~~~~~~~~~~~~~~~~~~~~^^^^^^^^^^^^^
TypeError: UserController.getUserByName() got an unexpected keyword argument 'name' - [_internal > _internal.py > _log]
12-12-2024,17:42:06 - ERROR - Error on request:
Traceback (most recent call last):
  File "/usr/local/lib/python3.13/site-packages/werkzeug/serving.py", line 370, in run_wsgi
    execute(self.server.app)
    ~~~~~~~^^^^^^^^^^^^^^^^^
  File "/usr/local/lib/python3.13/site-packages/werkzeug/serving.py", line 331, in execute
    application_iter = app(environ, start_response)
  File "/usr/local/lib/python3.13/site-packages/flask/app.py", line 1536, in __call__
    return self.wsgi_app(environ, start_response)
           ~~~~~~~~~~~~~^^^^^^^^^^^^^^^^^^^^^^^^^
  File "/usr/local/lib/python3.13/site-packages/flask/app.py", line 1514, in wsgi_app
    response = self.handle_exception(e)
  File "/usr/local/lib/python3.13/site-packages/flask/app.py", line 1511, in wsgi_app
    response = self.full_dispatch_request()
  File "/usr/local/lib/python3.13/site-packages/flask/app.py", line 919, in full_dispatch_request
    rv = self.handle_user_exception(e)
  File "/usr/local/lib/python3.13/site-packages/flask/app.py", line 917, in full_dispatch_request
    rv = self.dispatch_request()
  File "/usr/local/lib/python3.13/site-packages/flask/app.py", line 902, in dispatch_request
    return self.ensure_sync(self.view_functions[rule.endpoint])(**view_args)  # type: ignore[no-any-return]
           ~~~~~~~~~~~~~~~~~~~~~~~~~~~~~~~~~~~~~~~~~~~~~~~~~~~~^^^^^^^^^^^^^
TypeError: UserController.getUserByName() got an unexpected keyword argument 'name' - [_internal > _internal.py > _log]
12-12-2024,17:42:22 - ERROR - Error on request:
Traceback (most recent call last):
  File "/usr/local/lib/python3.13/site-packages/werkzeug/serving.py", line 370, in run_wsgi
    execute(self.server.app)
    ~~~~~~~^^^^^^^^^^^^^^^^^
  File "/usr/local/lib/python3.13/site-packages/werkzeug/serving.py", line 331, in execute
    application_iter = app(environ, start_response)
  File "/usr/local/lib/python3.13/site-packages/flask/app.py", line 1536, in __call__
    return self.wsgi_app(environ, start_response)
           ~~~~~~~~~~~~~^^^^^^^^^^^^^^^^^^^^^^^^^
  File "/usr/local/lib/python3.13/site-packages/flask/app.py", line 1514, in wsgi_app
    response = self.handle_exception(e)
  File "/usr/local/lib/python3.13/site-packages/flask/app.py", line 1511, in wsgi_app
    response = self.full_dispatch_request()
  File "/usr/local/lib/python3.13/site-packages/flask/app.py", line 919, in full_dispatch_request
    rv = self.handle_user_exception(e)
  File "/usr/local/lib/python3.13/site-packages/flask/app.py", line 917, in full_dispatch_request
    rv = self.dispatch_request()
  File "/usr/local/lib/python3.13/site-packages/flask/app.py", line 902, in dispatch_request
    return self.ensure_sync(self.view_functions[rule.endpoint])(**view_args)  # type: ignore[no-any-return]
           ~~~~~~~~~~~~~~~~~~~~~~~~~~~~~~~~~~~~~~~~~~~~~~~~~~~~^^^^^^^^^^^^^
TypeError: UserController.getUserByName() got an unexpected keyword argument 'name' - [_internal > _internal.py > _log]
12-12-2024,17:42:24 - ERROR - Error on request:
Traceback (most recent call last):
  File "/usr/local/lib/python3.13/site-packages/werkzeug/serving.py", line 370, in run_wsgi
    execute(self.server.app)
    ~~~~~~~^^^^^^^^^^^^^^^^^
  File "/usr/local/lib/python3.13/site-packages/werkzeug/serving.py", line 331, in execute
    application_iter = app(environ, start_response)
  File "/usr/local/lib/python3.13/site-packages/flask/app.py", line 1536, in __call__
    return self.wsgi_app(environ, start_response)
           ~~~~~~~~~~~~~^^^^^^^^^^^^^^^^^^^^^^^^^
  File "/usr/local/lib/python3.13/site-packages/flask/app.py", line 1514, in wsgi_app
    response = self.handle_exception(e)
  File "/usr/local/lib/python3.13/site-packages/flask/app.py", line 1511, in wsgi_app
    response = self.full_dispatch_request()
  File "/usr/local/lib/python3.13/site-packages/flask/app.py", line 919, in full_dispatch_request
    rv = self.handle_user_exception(e)
  File "/usr/local/lib/python3.13/site-packages/flask/app.py", line 917, in full_dispatch_request
    rv = self.dispatch_request()
  File "/usr/local/lib/python3.13/site-packages/flask/app.py", line 902, in dispatch_request
    return self.ensure_sync(self.view_functions[rule.endpoint])(**view_args)  # type: ignore[no-any-return]
           ~~~~~~~~~~~~~~~~~~~~~~~~~~~~~~~~~~~~~~~~~~~~~~~~~~~~^^^^^^^^^^^^^
TypeError: UserController.getUserByName() got an unexpected keyword argument 'name' - [_internal > _internal.py > _log]
12-12-2024,17:45:10 - ERROR - Error on request:
Traceback (most recent call last):
  File "/usr/local/lib/python3.13/site-packages/werkzeug/serving.py", line 370, in run_wsgi
    execute(self.server.app)
    ~~~~~~~^^^^^^^^^^^^^^^^^
  File "/usr/local/lib/python3.13/site-packages/werkzeug/serving.py", line 331, in execute
    application_iter = app(environ, start_response)
  File "/usr/local/lib/python3.13/site-packages/flask/app.py", line 1536, in __call__
    return self.wsgi_app(environ, start_response)
           ~~~~~~~~~~~~~^^^^^^^^^^^^^^^^^^^^^^^^^
  File "/usr/local/lib/python3.13/site-packages/flask/app.py", line 1514, in wsgi_app
    response = self.handle_exception(e)
  File "/usr/local/lib/python3.13/site-packages/flask/app.py", line 1511, in wsgi_app
    response = self.full_dispatch_request()
  File "/usr/local/lib/python3.13/site-packages/flask/app.py", line 919, in full_dispatch_request
    rv = self.handle_user_exception(e)
  File "/usr/local/lib/python3.13/site-packages/flask/app.py", line 917, in full_dispatch_request
    rv = self.dispatch_request()
  File "/usr/local/lib/python3.13/site-packages/flask/app.py", line 902, in dispatch_request
    return self.ensure_sync(self.view_functions[rule.endpoint])(**view_args)  # type: ignore[no-any-return]
           ~~~~~~~~~~~~~~~~~~~~~~~~~~~~~~~~~~~~~~~~~~~~~~~~~~~~^^^^^^^^^^^^^
TypeError: UserController.getUserByName() got an unexpected keyword argument 'name' - [_internal > _internal.py > _log]
12-12-2024,17:45:11 - ERROR - Error on request:
Traceback (most recent call last):
  File "/usr/local/lib/python3.13/site-packages/werkzeug/serving.py", line 370, in run_wsgi
    execute(self.server.app)
    ~~~~~~~^^^^^^^^^^^^^^^^^
  File "/usr/local/lib/python3.13/site-packages/werkzeug/serving.py", line 331, in execute
    application_iter = app(environ, start_response)
  File "/usr/local/lib/python3.13/site-packages/flask/app.py", line 1536, in __call__
    return self.wsgi_app(environ, start_response)
           ~~~~~~~~~~~~~^^^^^^^^^^^^^^^^^^^^^^^^^
  File "/usr/local/lib/python3.13/site-packages/flask/app.py", line 1514, in wsgi_app
    response = self.handle_exception(e)
  File "/usr/local/lib/python3.13/site-packages/flask/app.py", line 1511, in wsgi_app
    response = self.full_dispatch_request()
  File "/usr/local/lib/python3.13/site-packages/flask/app.py", line 919, in full_dispatch_request
    rv = self.handle_user_exception(e)
  File "/usr/local/lib/python3.13/site-packages/flask/app.py", line 917, in full_dispatch_request
    rv = self.dispatch_request()
  File "/usr/local/lib/python3.13/site-packages/flask/app.py", line 902, in dispatch_request
    return self.ensure_sync(self.view_functions[rule.endpoint])(**view_args)  # type: ignore[no-any-return]
           ~~~~~~~~~~~~~~~~~~~~~~~~~~~~~~~~~~~~~~~~~~~~~~~~~~~~^^^^^^^^^^^^^
TypeError: UserController.getUserByName() got an unexpected keyword argument 'name' - [_internal > _internal.py > _log]
12-12-2024,17:45:12 - ERROR - Error on request:
Traceback (most recent call last):
  File "/usr/local/lib/python3.13/site-packages/werkzeug/serving.py", line 370, in run_wsgi
    execute(self.server.app)
    ~~~~~~~^^^^^^^^^^^^^^^^^
  File "/usr/local/lib/python3.13/site-packages/werkzeug/serving.py", line 331, in execute
    application_iter = app(environ, start_response)
  File "/usr/local/lib/python3.13/site-packages/flask/app.py", line 1536, in __call__
    return self.wsgi_app(environ, start_response)
           ~~~~~~~~~~~~~^^^^^^^^^^^^^^^^^^^^^^^^^
  File "/usr/local/lib/python3.13/site-packages/flask/app.py", line 1514, in wsgi_app
    response = self.handle_exception(e)
  File "/usr/local/lib/python3.13/site-packages/flask/app.py", line 1511, in wsgi_app
    response = self.full_dispatch_request()
  File "/usr/local/lib/python3.13/site-packages/flask/app.py", line 919, in full_dispatch_request
    rv = self.handle_user_exception(e)
  File "/usr/local/lib/python3.13/site-packages/flask/app.py", line 917, in full_dispatch_request
    rv = self.dispatch_request()
  File "/usr/local/lib/python3.13/site-packages/flask/app.py", line 902, in dispatch_request
    return self.ensure_sync(self.view_functions[rule.endpoint])(**view_args)  # type: ignore[no-any-return]
           ~~~~~~~~~~~~~~~~~~~~~~~~~~~~~~~~~~~~~~~~~~~~~~~~~~~~^^^^^^^^^^^^^
TypeError: UserController.getUserByName() got an unexpected keyword argument 'name' - [_internal > _internal.py > _log]
12-12-2024,17:45:28 - ERROR - Error on request:
Traceback (most recent call last):
  File "/usr/local/lib/python3.13/site-packages/werkzeug/serving.py", line 370, in run_wsgi
    execute(self.server.app)
    ~~~~~~~^^^^^^^^^^^^^^^^^
  File "/usr/local/lib/python3.13/site-packages/werkzeug/serving.py", line 331, in execute
    application_iter = app(environ, start_response)
  File "/usr/local/lib/python3.13/site-packages/flask/app.py", line 1536, in __call__
    return self.wsgi_app(environ, start_response)
           ~~~~~~~~~~~~~^^^^^^^^^^^^^^^^^^^^^^^^^
  File "/usr/local/lib/python3.13/site-packages/flask/app.py", line 1514, in wsgi_app
    response = self.handle_exception(e)
  File "/usr/local/lib/python3.13/site-packages/flask/app.py", line 1511, in wsgi_app
    response = self.full_dispatch_request()
  File "/usr/local/lib/python3.13/site-packages/flask/app.py", line 919, in full_dispatch_request
    rv = self.handle_user_exception(e)
  File "/usr/local/lib/python3.13/site-packages/flask/app.py", line 917, in full_dispatch_request
    rv = self.dispatch_request()
  File "/usr/local/lib/python3.13/site-packages/flask/app.py", line 902, in dispatch_request
    return self.ensure_sync(self.view_functions[rule.endpoint])(**view_args)  # type: ignore[no-any-return]
           ~~~~~~~~~~~~~~~~~~~~~~~~~~~~~~~~~~~~~~~~~~~~~~~~~~~~^^^^^^^^^^^^^
TypeError: UserController.getUserByName() got an unexpected keyword argument 'name' - [_internal > _internal.py > _log]
12-12-2024,17:50:31 - ERROR - Error on request:
Traceback (most recent call last):
  File "/usr/local/lib/python3.13/site-packages/werkzeug/serving.py", line 370, in run_wsgi
    execute(self.server.app)
    ~~~~~~~^^^^^^^^^^^^^^^^^
  File "/usr/local/lib/python3.13/site-packages/werkzeug/serving.py", line 331, in execute
    application_iter = app(environ, start_response)
  File "/usr/local/lib/python3.13/site-packages/flask/app.py", line 1536, in __call__
    return self.wsgi_app(environ, start_response)
           ~~~~~~~~~~~~~^^^^^^^^^^^^^^^^^^^^^^^^^
  File "/usr/local/lib/python3.13/site-packages/flask/app.py", line 1514, in wsgi_app
    response = self.handle_exception(e)
  File "/usr/local/lib/python3.13/site-packages/flask/app.py", line 1511, in wsgi_app
    response = self.full_dispatch_request()
  File "/usr/local/lib/python3.13/site-packages/flask/app.py", line 919, in full_dispatch_request
    rv = self.handle_user_exception(e)
  File "/usr/local/lib/python3.13/site-packages/flask/app.py", line 917, in full_dispatch_request
    rv = self.dispatch_request()
  File "/usr/local/lib/python3.13/site-packages/flask/app.py", line 902, in dispatch_request
    return self.ensure_sync(self.view_functions[rule.endpoint])(**view_args)  # type: ignore[no-any-return]
           ~~~~~~~~~~~~~~~~~~~~~~~~~~~~~~~~~~~~~~~~~~~~~~~~~~~~^^^^^^^^^^^^^
TypeError: UserController.getUserByName() got an unexpected keyword argument 'name' - [_internal > _internal.py > _log]
12-12-2024,17:50:33 - ERROR - Error on request:
Traceback (most recent call last):
  File "/usr/local/lib/python3.13/site-packages/werkzeug/serving.py", line 370, in run_wsgi
    execute(self.server.app)
    ~~~~~~~^^^^^^^^^^^^^^^^^
  File "/usr/local/lib/python3.13/site-packages/werkzeug/serving.py", line 331, in execute
    application_iter = app(environ, start_response)
  File "/usr/local/lib/python3.13/site-packages/flask/app.py", line 1536, in __call__
    return self.wsgi_app(environ, start_response)
           ~~~~~~~~~~~~~^^^^^^^^^^^^^^^^^^^^^^^^^
  File "/usr/local/lib/python3.13/site-packages/flask/app.py", line 1514, in wsgi_app
    response = self.handle_exception(e)
  File "/usr/local/lib/python3.13/site-packages/flask/app.py", line 1511, in wsgi_app
    response = self.full_dispatch_request()
  File "/usr/local/lib/python3.13/site-packages/flask/app.py", line 919, in full_dispatch_request
    rv = self.handle_user_exception(e)
  File "/usr/local/lib/python3.13/site-packages/flask/app.py", line 917, in full_dispatch_request
    rv = self.dispatch_request()
  File "/usr/local/lib/python3.13/site-packages/flask/app.py", line 902, in dispatch_request
    return self.ensure_sync(self.view_functions[rule.endpoint])(**view_args)  # type: ignore[no-any-return]
           ~~~~~~~~~~~~~~~~~~~~~~~~~~~~~~~~~~~~~~~~~~~~~~~~~~~~^^^^^^^^^^^^^
TypeError: UserController.getUserByName() got an unexpected keyword argument 'name' - [_internal > _internal.py > _log]
12-12-2024,17:54:44 - ERROR - Error on request:
Traceback (most recent call last):
  File "/usr/local/lib/python3.13/site-packages/werkzeug/serving.py", line 370, in run_wsgi
    execute(self.server.app)
    ~~~~~~~^^^^^^^^^^^^^^^^^
  File "/usr/local/lib/python3.13/site-packages/werkzeug/serving.py", line 331, in execute
    application_iter = app(environ, start_response)
  File "/usr/local/lib/python3.13/site-packages/flask/app.py", line 1536, in __call__
    return self.wsgi_app(environ, start_response)
           ~~~~~~~~~~~~~^^^^^^^^^^^^^^^^^^^^^^^^^
  File "/usr/local/lib/python3.13/site-packages/flask/app.py", line 1514, in wsgi_app
    response = self.handle_exception(e)
  File "/usr/local/lib/python3.13/site-packages/flask/app.py", line 1511, in wsgi_app
    response = self.full_dispatch_request()
  File "/usr/local/lib/python3.13/site-packages/flask/app.py", line 919, in full_dispatch_request
    rv = self.handle_user_exception(e)
  File "/usr/local/lib/python3.13/site-packages/flask/app.py", line 917, in full_dispatch_request
    rv = self.dispatch_request()
  File "/usr/local/lib/python3.13/site-packages/flask/app.py", line 902, in dispatch_request
    return self.ensure_sync(self.view_functions[rule.endpoint])(**view_args)  # type: ignore[no-any-return]
           ~~~~~~~~~~~~~~~~~~~~~~~~~~~~~~~~~~~~~~~~~~~~~~~~~~~~^^^^^^^^^^^^^
TypeError: UserController.delUser() got an unexpected keyword argument 'name' - [_internal > _internal.py > _log]
